Traceback (most recent call last):
  File "/home/aymeric/anaconda3/envs/analyse_tweets/lib/python3.9/site-packages/jupyter_cache/executors/utils.py", line 51, in single_nb_execution
    executenb(
  File "/home/aymeric/anaconda3/envs/analyse_tweets/lib/python3.9/site-packages/nbclient/client.py", line 1093, in execute
    return NotebookClient(nb=nb, resources=resources, km=km, **kwargs).execute()
  File "/home/aymeric/anaconda3/envs/analyse_tweets/lib/python3.9/site-packages/nbclient/util.py", line 84, in wrapped
    return just_run(coro(*args, **kwargs))
  File "/home/aymeric/anaconda3/envs/analyse_tweets/lib/python3.9/site-packages/nbclient/util.py", line 62, in just_run
    return loop.run_until_complete(coro)
  File "/home/aymeric/anaconda3/envs/analyse_tweets/lib/python3.9/asyncio/base_events.py", line 642, in run_until_complete
    return future.result()
  File "/home/aymeric/anaconda3/envs/analyse_tweets/lib/python3.9/site-packages/nbclient/client.py", line 559, in async_execute
    await self.async_execute_cell(
  File "/home/aymeric/anaconda3/envs/analyse_tweets/lib/python3.9/site-packages/nbclient/client.py", line 854, in async_execute_cell
    self._check_raise_for_error(cell, exec_reply)
  File "/home/aymeric/anaconda3/envs/analyse_tweets/lib/python3.9/site-packages/nbclient/client.py", line 756, in _check_raise_for_error
    raise CellExecutionError.from_cell_and_msg(cell, exec_reply_content)
nbclient.exceptions.CellExecutionError: An error occurred while executing the following cell:
------------------
d = dftext.dropna(subset=["Synthetic_logics"])
df_rank = ranked_element(data = d, which="Synthetic_logics", top_rank= None)
bump = interactive_bump_chart(data = df_rank, which = "Synthetic_logics", cluster = None)
------------------

[0;31m---------------------------------------------------------------------------[0m
[0;31mAttributeError[0m                            Traceback (most recent call last)
[0;32m/tmp/ipykernel_9838/3311158067.py[0m in [0;36m<module>[0;34m[0m
[1;32m      1[0m [0md[0m [0;34m=[0m [0mdftext[0m[0;34m.[0m[0mdropna[0m[0;34m([0m[0msubset[0m[0;34m=[0m[0;34m[[0m[0;34m"Synthetic_logics"[0m[0;34m][0m[0;34m)[0m[0;34m[0m[0;34m[0m[0m
[1;32m      2[0m [0mdf_rank[0m [0;34m=[0m [0mranked_element[0m[0;34m([0m[0mdata[0m [0;34m=[0m [0md[0m[0;34m,[0m [0mwhich[0m[0;34m=[0m[0;34m"Synthetic_logics"[0m[0;34m,[0m [0mtop_rank[0m[0;34m=[0m [0;32mNone[0m[0;34m)[0m[0;34m[0m[0;34m[0m[0m
[0;32m----> 3[0;31m [0mbump[0m [0;34m=[0m [0minteractive_bump_chart[0m[0;34m([0m[0mdata[0m [0;34m=[0m [0mdf_rank[0m[0;34m,[0m [0mwhich[0m [0;34m=[0m [0;34m"Synthetic_logics"[0m[0;34m,[0m [0mcluster[0m [0;34m=[0m [0;32mNone[0m[0;34m)[0m[0;34m[0m[0;34m[0m[0m
[0m
[0;32m/tmp/ipykernel_9838/1961923264.py[0m in [0;36minteractive_bump_chart[0;34m(data, which, cluster)[0m
[1;32m     10[0m     [0mfig[0m[0;34m[[0m[0;34m'layout'[0m[0;34m][0m[0;34m[[0m[0;34m'yaxis'[0m[0;34m][0m[0;34m[[0m[0;34m'autorange'[0m[0;34m][0m [0;34m=[0m [0;34m"reversed"[0m[0;34m[0m[0;34m[0m[0m
[1;32m     11[0m [0;34m[0m[0m
[0;32m---> 12[0;31m     [0mfig[0m[0;34m.[0m[0mset_xlabel[0m[0;34m([0m[0;34mf'{x}'[0m[0;34m,[0m [0mfontsize[0m [0;34m=[0m [0;36m14[0m[0;34m)[0m[0;34m[0m[0;34m[0m[0m
[0m[1;32m     13[0m     [0mfig[0m[0;34m.[0m[0mset_ylabel[0m[0;34m([0m[0;34m"Rank"[0m[0;34m,[0m [0mfontsize[0m [0;34m=[0m [0;36m14[0m[0;34m)[0m[0;34m[0m[0;34m[0m[0m
[1;32m     14[0m [0;34m[0m[0m

[0;31mAttributeError[0m: 'Figure' object has no attribute 'set_xlabel'
AttributeError: 'Figure' object has no attribute 'set_xlabel'

